Workbook
Name _DLX1.INC: Haver!$2:$11
Name _DLX2.INC: Haver_M!$2:$11
Name _DLX3.INC: UK_HAVER!$1:$13
Name Data: [1]sheet0!$C$2

Sheet matlab
A1: date | B1: EZGDP | C1: USGDP | D1: UKGDP | E1: CHGDP | F1: EZCPI | G1: USCPI | H1: UKCPI | I1: CHCPI | J1: EZRR | K1: USRR | L1: UKRR | M1: CHRR | N1: USDEUR | O1: USDGBP | P1: USDCNY | Q1: VIX | R1: POIL | S1: EZ10Y
A2: 29281 | B2: =AWM!B42 -> 1561462.5 | C2: =Haver!D12 -> 1835.4 | D2: =UK_HAVER!C14 -> 290378 | E2: =E3/(OEM!E8/OEM!E7) -> 711.63119 | F2: =AWM!D42 -> 33.126531 | G2: =Haver!N12 -> 79.033333 | H2: =UK_HAVER!E14 -> #N/A | J2: =AWM!C42 -> 12.735107 | K2: =OEM!D7 -> 13.93896 | L2: =UK_HAVER!D14 -> 17 | M2: =M3/(OEM_aux!B8/OEM_aux!B7) -> 4.4873495 | N2: =Haver!J12 -> 0.70891484 | O2: =1/UK_HAVER!F14 -> 0.44393803 | P2: =1/ '[2]Exchange rate'!$C7 -> 0.0058788256
A3: 29373 | B3: =AWM!B43 -> 1554130.5 | C3: =Haver!D13 -> 1797.6 | D3: =UK_HAVER!C15 -> 284713 | E3: =E4/(OEM!E9/OEM!E8) -> 726.11643 | F3: =AWM!D43 -> 33.986161 | G3: =Haver!N13 -> 81.7 | H3: =UK_HAVER!E15 -> #N/A | J3: =AWM!C43 -> 13.23709 | K3: =OEM!D8 -> 11.7426 | L3: =UK_HAVER!D15 -> 17 | M3: =M4/(OEM_aux!B9/OEM_aux!B8) -> 4.4873495 | N3: =Haver!J13 -> 0.71904683 | O3: =1/UK_HAVER!F15 -> 0.4381289 | P3: =1/ '[2]Exchange rate'!$C8 -> 0.005810663 | S3: =Mater_Q!B4 -> 8.7113333
A4: 29465 | B4: =AWM!B44 -> 1553244.6 | C4: =Haver!D14 -> 1795.4 | D4: =UK_HAVER!C16 -> 284402 | E4: =E5/(OEM!E10/OEM!E9) -> 740.12672 | F4: =AWM!D44 -> 34.767567 | G4: =Haver!N14 -> 83.233333 | H4: =UK_HAVER!E16 -> #N/A | J4: =AWM!C44 -> 12.239029 | K4: =OEM!D9 -> 9.094363 | L4: =UK_HAVER!D16 -> 16.03 | M4: =M5/(OEM_aux!B10/OEM_aux!B9) -> 4.4873495 | N4: =Haver!J14 -> 0.70283289 | O4: =1/UK_HAVER!F16 -> 0.41988579 | P4: =1/ '[2]Exchange rate'!$C9 -> 0.0057418828 | S4: =Mater_Q!B5 -> 7.989
A5: 29556 | B5: =AWM!B45 -> 1553974.2 | C5: =Haver!D15 -> 1828.9 | D5: =UK_HAVER!C17 -> 281496 | E5: =E6/(OEM!E11/OEM!E10) -> 755.51459 | F5: =AWM!D45 -> 35.621301 | G5: =Haver!N15 -> 85.566667 | H5: =UK_HAVER!E17 -> #N/A | J5: =AWM!C45 -> 12.663299 | K5: =OEM!D10 -> 14.72999 | L5: =UK_HAVER!D17 -> 15.2 | M5: =M6/(OEM_aux!B11/OEM_aux!B10) -> 4.4873495 | N5: =Haver!J15 -> 0.74632621 | O5: =1/UK_HAVER!F17 -> 0.41919933 | P5: =1/ '[2]Exchange rate'!$C10 -> 0.0058378513 | S5: =Mater_Q!B6 -> 8.642
A6: 29646 | B6: =AWM!B46 -> 1555473.6 | C6: =Haver!D16 -> 1864.8 | D6: =UK_HAVER!C18 -> 281257 | E6: =E7/(OEM!E12/OEM!E11) -> 746.28871 | F6: =AWM!D46 -> 36.78482 | G6: =Haver!N16 -> 87.933333 | H6: =UK_HAVER!E18 -> #N/A | J6: =AWM!C46 -> 13.432882 | K6: =OEM!D11 -> 15.40231 | L6: =UK_HAVER!D18 -> 13.546667 | M6: =M7/(OEM_aux!B12/OEM_aux!B11) -> 4.4873495 | N6: =Haver!J16 -> 0.81110895 | O6: =1/UK_HAVER!F18 -> 0.43296916 | P6: =1/ '[2]Exchange rate'!$C11 -> 0.0060103992 | S6: =Mater_Q!B7 -> 9.6076667
A7: 29738 | B7: =AWM!B47 -> 1560133.1 | C7: =Haver!D17 -> 1850.9 | D7: =UK_HAVER!C19 -> 282155 | E7: =E8/(OEM!E13/OEM!E12) -> 762.60048 | F7: =AWM!D47 -> 37.768239 | G7: =Haver!N17 -> 89.766667 | H7: =UK_HAVER!E19 -> #N/A | J7: =AWM!C47 -> 15.507875 | K7: =OEM!D12 -> 16.51873 | L7: =UK_HAVER!D19 -> 12 | M7: =M8/(OEM_aux!B13/OEM_aux!B12) -> 4.4873495 | N7: =Haver!J17 -> 0.89624206 | O7: =1/UK_HAVER!F19 -> 0.48096192 | P7: =1/ '[2]Exchange rate'!$C12 -> 0.0061633814 | S7: =Mater_Q!B8 -> 10.304333
A8: 29830 | B8: =AWM!B48 -> 1564437.5 | C8: =Haver!D18 -> 1873.1 | D8: =UK_HAVER!C20 -> 285437 | E8: =E9/(OEM!E14/OEM!E13) -> 778.4717 | F8: =AWM!D48 -> 38.724472 | G8: =Haver!N18 -> 92.266667 | H8: =UK_HAVER!E20 -> #N/A | J8: =AWM!C48 -> 16.133415 | K8: =OEM!D13 -> 16.47078 | L8: =UK_HAVER!D20 -> 12.513333 | M8: =M9/(OEM_aux!B14/OEM_aux!B13) -> 4.4873495 | N8: =Haver!J18 -> 0.96849799 | O8: =1/UK_HAVER!F20 -> 0.54460298 | P8: =1/ '[2]Exchange rate'!$C13 -> 0.006081741 | S8: =Mater_Q!B9 -> 10.558667
A9: 29921 | B9: =AWM!B49 -> 1568108.4 | C9: =Haver!D19 -> 1852.7 | D9: =UK_HAVER!C21 -> 285814 | E9: =E10/(OEM!E15/OEM!E14) -> 795.75611 | F9: =AWM!D49 -> 39.745347 | G9: =Haver!N19 -> 93.766667 | H9: =UK_HAVER!E21 -> #N/A | J9: =AWM!C49 -> 15.426309 | K9: =OEM!D14 -> 12.66561 | L9: =UK_HAVER!D21 -> 14.61 | M9: =M10/(OEM_aux!B15/OEM_aux!B14) -> 4.4873495 | N9: =Haver!J19 -> 0.91801513 | O9: =1/UK_HAVER!F21 -> 0.53130258 | P9: =1/ '[2]Exchange rate'!$C14 -> 0.0060732605 | S9: =Mater_Q!B10 -> 9.9646667
A10: 30011 | B10: =AWM!B50 -> 1574589.1 | C10: =Haver!D20 -> 1823.9 | D10: =UK_HAVER!C22 -> 286275 | E10: =E11/(OEM!E16/OEM!E15) -> 811.15802 | F10: =AWM!D50 -> 40.729084 | G10: =Haver!N20 -> 94.6 | H10: =UK_HAVER!E22 -> #N/A | J10: =AWM!C50 -> 14.331319 | K10: =OEM!D15 -> 13.27632 | L10: =UK_HAVER!D22 -> 13.793333 | M10: =M11/(OEM_aux!B16/OEM_aux!B15) -> 7.2833131 | N10: =Haver!J20 -> 0.96385852 | O10: =1/UK_HAVER!F22 -> 0.54168247 | P10: =1/ '[2]Exchange rate'!$C15 -> 0.0060699612 | S10: =Mater_Q!B11 -> 9.6733333
A11: 30103 | B11: =AWM!B51 -> 1576706.9 | C11: =Haver!D21 -> 1832.2 | D11: =UK_HAVER!C23 -> 289232 | E11: =E12/(OEM!E17/OEM!E16) -> 829.90071 | F11: =AWM!D51 -> 41.674783 | G11: =Haver!N21 -> 95.966667 | H11: =UK_HAVER!E23 -> #N/A | J11: =AWM!C51 -> 14.400041 | K11: =OEM!D16 -> 13.51189 | L11: =UK_HAVER!D23 -> 13.016667 | M11: =M12/(OEM_aux!B17/OEM_aux!B16) -> 7.2833131 | N11: =Haver!J21 -> 0.99683737 | O11: =1/UK_HAVER!F23 -> 0.56193455 | P11: =1/ '[2]Exchange rate'!$C16 -> 0.0060194259 | S11: =Mater_Q!B12 -> 8.9833333
A12: 30195 | B12: =AWM!B52 -> 1568297.1 | C12: =Haver!D22 -> 1825.2 | D12: =UK_HAVER!C24 -> 289852 | E12: =E13/(OEM!E18/OEM!E17) -> 849.51646 | F12: =AWM!D52 -> 42.478199 | G12: =Haver!N22 -> 97.633333 | H12: =UK_HAVER!E24 -> #N/A | J12: =AWM!C52 -> 13.349537 | K12: =Haver!H22 -> 10.25 | L12: =UK_HAVER!D24 -> 11.353333 | M12: =M13/(OEM_aux!B18/OEM_aux!B17) -> 7.2833131 | N12: =Haver!J22 -> 1.0519222 | O12: =1/UK_HAVER!F24 -> 0.58000155 | P12: =1/ '[2]Exchange rate'!$C17 -> 0.0060098971 | S12: =Mater_Q!B13 -> 8.9873333
A13: 30286 | B13: =AWM!B53 -> 1568970 | C13: =Haver!D23 -> 1826 | D13: =UK_HAVER!C25 -> 291832 | E13: =E14/(OEM!E19/OEM!E18) -> 869.93506 | F13: =AWM!D53 -> 43.293676 | G13: =Haver!N23 -> 97.933333 | H13: =UK_HAVER!E25 -> #N/A | J13: =AWM!C53 -> 12.606617 | K13: =Haver!H23 -> 8.5 | L13: =UK_HAVER!D25 -> 9.6833333 | M13: =M14/(OEM_aux!B19/OEM_aux!B18) -> 7.2833131 | N13: =Haver!J23 -> 1.0711849 | O13: =1/UK_HAVER!F25 -> 0.6067593 | P13: =1/ '[2]Exchange rate'!$C18 -> 0.0059951463 | S13: =Mater_Q!B14 -> 8.2193333
A14: 30376 | B14: =AWM!B54 -> 1579416.4 | C14: =Haver!D24 -> 1850 | D14: =UK_HAVER!C26 -> 297563 | E14: =E15/(OEM!E20/OEM!E19) -> 895.49387 | F14: =AWM!D54 -> 44.173742 | G14: =Haver!N24 -> 98 | H14: =UK_HAVER!E26 -> #N/A | J14: =AWM!C54 -> 11.886462 | K14: =Haver!H24 -> 8.625 | L14: =UK_HAVER!D26 -> 10.816667 | M14: =M15/(OEM_aux!B20/OEM_aux!B19) -> 7.2833131 | N14: =Haver!J24 -> 1.0548208 | O14: =1/UK_HAVER!F26 -> 0.65238665 | P14: =1/ '[2]Exchange rate'!$C19 -> 0.0059405599 | S14: =Mater_Q!B15 -> 7.6146667
A15: 30468 | B15: =AWM!B55 -> 1589751.1 | C15: =Haver!D25 -> 1892.1 | D15: =UK_HAVER!C27 -> 299623 | E15: =E16/(OEM!E21/OEM!E20) -> 918.24915 | F15: =AWM!D55 -> 44.935485 | G15: =Haver!N25 -> 99.133333 | H15: =UK_HAVER!E27 -> #N/A | J15: =AWM!C55 -> 11.847545 | K15: =Haver!H25 -> 9 | L15: =UK_HAVER!D27 -> 10.016667 | M15: =M16/(OEM_aux!B21/OEM_aux!B20) -> 7.2833131 | N15: =Haver!J25 -> 1.0964135 | O15: =1/UK_HAVER!F27 -> 0.64428838 | P15: =1/ '[2]Exchange rate'!$C20 -> 0.0058727631 | S15: =Mater_Q!B16 -> 7.7703333
A16: 30560 | B16: =AWM!B56 -> 1593881.2 | C16: =Haver!D26 -> 1929.9 | D16: =UK_HAVER!C28 -> 303085 | E16: =E17/(OEM!E22/OEM!E21) -> 942.61391 | F16: =AWM!D56 -> 45.68737 | G16: =Haver!N26 -> 100.1 | H16: =UK_HAVER!E28 -> #N/A | J16: =AWM!C56 -> 12.21865 | K16: =Haver!H26 -> 9.375 | L16: =UK_HAVER!D28 -> 9.56 | M16: =M17/(OEM_aux!B22/OEM_aux!B21) -> 7.2833131 | N16: =Haver!J26 -> 1.1613215 | O16: =1/UK_HAVER!F28 -> 0.66247102 | P16: =1/ '[2]Exchange rate'!$C21 -> 0.0056806014 | S16: =Mater_Q!B17 -> 8.361
A17: 30651 | B17: =AWM!B57 -> 1611312.5 | C17: =Haver!D27 -> 1970.2 | D17: =UK_HAVER!C29 -> 305361 | E17: =E18/(OEM!E23/OEM!E22) -> 965.49596 | F17: =AWM!D57 -> 46.475521 | G17: =Haver!N27 -> 101.1 | H17: =UK_HAVER!E29 -> #N/A | J17: =AWM!C57 -> 12.169143 | K17: =Haver!H27 -> 9.375 | L17: =UK_HAVER!D29 -> 9.06 | M17: =M18/(OEM_aux!B23/OEM_aux!B22) -> 7.2833131 | N17: =Haver!J27 -> 1.1850185 | O17: =1/UK_HAVER!F29 -> 0.68068886 | P17: =1/ '[2]Exchange rate'!$C22 -> 0.0055921406 | S17: =Mater_Q!B18 -> 8.3263333
A18: 30742 | B18: =AWM!B58 -> 1625156.1 | C18: =Haver!D28 -> 2008.7 | D18: =UK_HAVER!C30 -> 307964 | E18: =E19/(OEM!E24/OEM!E23) -> 1029.5956 | F18: =AWM!D58 -> 47.308976 | G18: =Haver!N28 -> 102.53333 | H18: =UK_HAVER!E30 -> #N/A | J18: =AWM!C58 -> 11.43169 | K18: =Haver!H28 -> 10.5 | L18: =UK_HAVER!D30 -> 8.9433333 | M18: =M19/(OEM_aux!B24/OEM_aux!B23) -> 7.2833131 | N18: =Haver!J28 -> 1.2024318 | O18: =1/UK_HAVER!F30 -> 0.69686411 | P18: =1/ '[2]Exchange rate'!$C23 -> 0.0057242328 | S18: =Mater_Q!B19 -> 8.2333333
A19: 30834 | B19: =AWM!B59 -> 1617476.5 | C19: =Haver!D29 -> 2043.4 | D19: =UK_HAVER!C31 -> 304892 | E19: =E20/(OEM!E25/OEM!E24) -> 1056.8872 | F19: =AWM!D59 -> 47.937614 | G19: =Haver!N29 -> 103.5 | H19: =UK_HAVER!E31 -> #N/A | I19: =reconstruct_levels_ch!D19 -> 16.953213 | J19: =AWM!C59 -> 10.857933 | K19: =Haver!H29 -> 10.5 | L19: =UK_HAVER!D31 -> 8.8433333 | M19: =M20/(OEM_aux!B25/OEM_aux!B24) -> 7.2833131 | N19: =Haver!J29 -> 1.2116977 | O19: =1/UK_HAVER!F31 -> 0.71643502 | P19: =1/ '[2]Exchange rate'!$C24 -> 0.0059476264 | S19: =Mater_Q!B20 -> 8.188
A20: 30926 | B20: =AWM!B60 -> 1634152.6 | C20: =Haver!D30 -> 2063.1 | D20: =UK_HAVER!C32 -> 307122 | E20: =E21/(OEM!E26/OEM!E25) -> 1086.3049 | F20: =AWM!D60 -> 48.424678 | G20: =Haver!N30 -> 104.4 | H20: =UK_HAVER!E32 -> #N/A | I20: =reconstruct_levels_ch!D20 -> 17.05617 | J20: =AWM!C60 -> 10.413573 | K20: =Haver!H30 -> 11 | L20: =UK_HAVER!D32 -> 10.89 | M20: =M21/(OEM_aux!B26/OEM_aux!B25) -> 7.2833131 | N20: =Haver!J30 -> 1.3025972 | O20: =1/UK_HAVER!F32 -> 0.77130737 | P20: =1/ '[2]Exchange rate'!$C25 -> 0.006309626 | S20: =Mater_Q!B21 -> 8.0836667
A21: 31017 | B21: =AWM!B61 -> 1642515.5 | C21: =Haver!D31 -> 2080.1 | D21: =UK_HAVER!C33 -> 312697 | E21: =E22/(OEM!E27/OEM!E26) -> 1113.4679 | F21: =AWM!D61 -> 49.042148 | G21: =Haver!N31 -> 105.3 | H21: =UK_HAVER!E33 -> #N/A | I21: =reconstruct_levels_ch!D21 -> 17.209847 | J21: =AWM!C61 -> 10.128111 | K21: =Haver!H31 -> 8.125 | L21: =UK_HAVER!D33 -> 9.9533333 | M21: =M22/(OEM_aux!B27/OEM_aux!B26) -> 7.2833131 | N21: =Haver!J31 -> 1.3673007 | O21: =1/UK_HAVER!F33 -> 0.82306785 | P21: =1/ '[2]Exchange rate'!$C26 -> 0.0067990209 | S21: =Mater_Q!B22 -> 7.29
A22: 31107 | B22: =AWM!B62 -> 1646206.4 | C22: =Haver!D32 -> 2100.2 | D22: =UK_HAVER!C34 -> 315753 | E22: =E23/(OEM!E28/OEM!E27) -> 1166.2879 | F22: =AWM!D62 -> 49.862985 | G22: =Haver!N32 -> 106.26667 | H22: =UK_HAVER!E34 -> #N/A | I22: =reconstruct_levels_ch!D22 -> 17.915297 | J22: =AWM!C62 -> 9.8634286 | K22: =Haver!H32 -> 8.5 | L22: =UK_HAVER!D34 -> 12.966667 | M22: =M23/(OEM_aux!B28/OEM_aux!B27) -> 7.2833131 | N22: =Haver!J32 -> 1.4618729 | O22: =1/UK_HAVER!F34 -> 0.89672695 | P22: =1/ '[2]Exchange rate'!$C27 -> 0.0068723043 | S22: =Mater_Q!B23 -> 7.4443333
A23: 31199 | B23: =AWM!B63 -> 1661914.3 | C23: =Haver!D33 -> 2118.7 | D23: =UK_HAVER!C35 -> 322451 | E23: =E24/(OEM!E29/OEM!E28) -> 1199.0291 | F23: =AWM!D63 -> 50.535072 | G23: =Haver!N33 -> 107.23333 | H23: =UK_HAVER!E35 -> #N/A | I23: =reconstruct_levels_ch!D23 -> 18.539499 | J23: =AWM!C63 -> 9.9615894 | K23: =Haver!H33 -> 7.75 | L23: =UK_HAVER!D35 -> 12.48 | M23: =M24/(OEM_aux!B29/OEM_aux!B28) -> 8.215301 | N23: =Haver!J33 -> 1.3773757 | O23: =1/UK_HAVER!F35 -> 0.79643198 | P23: =1/ '[2]Exchange rate'!$C28 -> 0.0069632937 | S23: =Mater_Q!B24 -> 7.1856667
A24: 31291 | B24: =AWM!B64 -> 1675982.7 | C24: =Haver!D34 -> 2151.1 | D24: =UK_HAVER!C36 -> 322392 | E24: =E25/(OEM!E30/OEM!E29) -> 1231.711 | F24: =AWM!D64 -> 50.78839 | G24: =Haver!N34 -> 107.9 | H24: =UK_HAVER!E36 -> #N/A | I24: =reconstruct_levels_ch!D24 -> 18.959105 | J24: =AWM!C64 -> 9.3468045 | K24: =Haver!H34 -> 8 | L24: =UK_HAVER!D36 -> 11.573333 | M24: =M25/(OEM_aux!B30/OEM_aux!B29) -> 8.215301 | N24: =Haver!J34 -> 1.2739995 | O24: =1/UK_HAVER!F36 -> 0.72656818 | P24: =1/ '[2]Exchange rate'!$C29 -> 0.00721368 | S24: =Mater_Q!B25 -> 6.616
A25: 31382 | B25: =AWM!B65 -> 1685974.7 | C25: =Haver!D35 -> 2167.1 | D25: =UK_HAVER!C37 -> 322604 | E25: =E26/(OEM!E31/OEM!E30) -> 1261.5479 | F25: =AWM!D65 -> 51.210371 | G25: =Haver!N35 -> 109 | H25: =UK_HAVER!E37 -> #N/A | I25: =reconstruct_levels_ch!D25 -> 19.139532 | J25: =AWM!C65 -> 8.627972 | K25: =Haver!H35 -> 7.75 | L25: =UK_HAVER!D37 -> 11.38 | M25: =M26/(OEM_aux!B31/OEM_aux!B30) -> 8.215301 | N25: =Haver!J35 -> 1.1713136 | O25: =1/UK_HAVER!F37 -> 0.69673464 | P25: =1/ '[2]Exchange rate'!$C30 -> 0.0080715006 | S25: =Mater_Q!B26 -> 6.5403333
A26: 31472 | B26: =AWM!B66 -> 1680223 | C26: =Haver!D36 -> 2187.3 | D26: =UK_HAVER!C38 -> 325968 | E26: =E27/(OEM!E32/OEM!E31) -> 1271.571 | F26: =AWM!D66 -> 51.615763 | G26: =Haver!N36 -> 109.56667 | H26: =UK_HAVER!E38 -> #N/A | I26: =reconstruct_levels_ch!D26 -> 19.369935 | J26: =AWM!C66 -> 8.7486202 | K26: =Haver!H36 -> 7.25 | L26: =UK_HAVER!D38 -> 12.12 | M26: =M27/(OEM_aux!B32/OEM_aux!B31) -> 8.215301 | N26: =Haver!J36 -> 1.0817094 | O26: =1/UK_HAVER!F38 -> 0.6942034 | P26: =1/ '[2]Exchange rate'!$C31 -> 0.0083729093 | S26: =Mater_Q!B27 -> 6.095
A27: 31564 | B27: =AWM!B67 -> 1711030.4 | C27: =Haver!D37 -> 2197.1 | D27: =UK_HAVER!C39 -> 328872 | E27: =E28/(OEM!E33/OEM!E32) -> 1306.9911 | F27: =AWM!D67 -> 51.818958 | G27: =Haver!N37 -> 109.03333 | H27: =UK_HAVER!E39 -> #N/A | I27: =reconstruct_levels_ch!D27 -> 19.422583 | J27: =AWM!C67 -> 8.0283937 | K27: =Haver!H37 -> 6.875 | L27: =UK_HAVER!D39 -> 10.326667 | M27: =M28/(OEM_aux!B33/OEM_aux!B32) -> 8.215301 | N27: =Haver!J37 -> 1.0427982 | O27: =1/UK_HAVER!F39 -> 0.66252954 | P27: =1/ '[2]Exchange rate'!$C32 -> 0.0084876602 | S27: =Mater_Q!B28 -> 5.6593333
A28: 31656 | B28: =AWM!B68 -> 1719722.7 | C28: =Haver!D38 -> 2218.2 | D28: =UK_HAVER!C40 -> 330966 | E28: =E29/(OEM!E34/OEM!E33) -> 1340.2188 | F28: =AWM!D68 -> 51.961723 | G28: =Haver!N38 -> 109.7 | H28: =UK_HAVER!E40 -> #N/A | I28: =reconstruct_levels_ch!D28 -> 19.737391 | J28: =AWM!C68 -> 7.7533413 | K28: =Haver!H38 -> 5.875 | L28: =UK_HAVER!D40 -> 9.88 | M28: =M29/(OEM_aux!B34/OEM_aux!B33) -> 8.215301 | N28: =Haver!J38 -> 0.98696515 | O28: =1/UK_HAVER!F40 -> 0.67219359 | P28: =1/ '[2]Exchange rate'!$C33 -> 0.0099288794 | R28: =Haver!R38 -> 12.316667 | S28: =Mater_Q!B29 -> 5.731
A29: 31747 | B29: =AWM!B69 -> 1723981.4 | C29: =Haver!D39 -> 2230.1 | D29: =UK_HAVER!C41 -> 337367 | E29: =E30/(OEM!E35/OEM!E34) -> 1371.7743 | F29: =AWM!D69 -> 52.142784 | G29: =Haver!N39 -> 110.46667 | H29: =UK_HAVER!E41 -> #N/A | I29: =reconstruct_levels_ch!D29 -> 20.219317 | J29: =AWM!C69 -> 7.8747736 | K29: =Haver!H39 -> 5.875 | L29: =UK_HAVER!D41 -> 10.733333 | M29: =M30/(OEM_aux!B35/OEM_aux!B34) -> 8.215301 | N29: =Haver!J39 -> 0.96334164 | O29: =1/UK_HAVER!F41 -> 0.69938221 | P29: =1/ '[2]Exchange rate'!$C34 -> 0.0099319266 | R29: =Haver!R39 -> 14.676667 | S29: =Mater_Q!B30 -> 6.0893333
A30: 31837 | B30: =AWM!B70 -> 1715707.6 | C30: =Haver!D40 -> 2246.6 | D30: =UK_HAVER!C42 -> 339754 | E30: =E31/(OEM!E36/OEM!E35) -> 1422.764 | F30: =AWM!D70 -> 52.622287 | G30: =Haver!N40 -> 111.8 | H30: =UK_HAVER!E42 -> #N/A | I30: =reconstruct_levels_ch!D30 -> 20.472642 | J30: =AWM!C70 -> 8.105353 | K30: =Haver!H40 -> 6 | L30: =UK_HAVER!D42 -> 10.673333 | M30: =M31/(OEM_aux!B36/OEM_aux!B35) -> 8.215301 | N30: =Haver!J40 -> 0.88926304 | O30: =1/UK_HAVER!F42 -> 0.64855049 | P30: =1/ '[2]Exchange rate'!$C35 -> 0.010162573 | R30: =Haver!R40 -> 17.87 | S30: =Mater_Q!B31 -> 5.9233333
A31: 31929 | B31: =AWM!B71 -> 1744613 | C31: =Haver!D41 -> 2270.8 | D31: =UK_HAVER!C43 -> 344795 | E31: =E32/(OEM!E37/OEM!E36) -> 1462.3531 | F31: =AWM!D71 -> 52.976874 | G31: =Haver!N41 -> 113.06667 | H31: =UK_HAVER!E43 -> #N/A | I31: =reconstruct_levels_ch!D31 -> 20.903646 | J31: =AWM!C71 -> 8.4258269 | K31: =Haver!H41 -> 6.75 | L31: =UK_HAVER!D43 -> 9.22 | M31: =M32/(OEM_aux!B37/OEM_aux!B36) -> 8.215301 | N31: =Haver!J41 -> 0.86945685 | O31: =1/UK_HAVER!F43 -> 0.60892687 | P31: =1/ '[2]Exchange rate'!$C36 -> 0.010301683 | R31: =Haver!R41 -> 18.666667 | S31: =Mater_Q!B32 -> 5.664
A32: 32021 | B32: =AWM!B72 -> 1763348.5 | C32: =Haver!D42 -> 2290.5 | D32: =UK_HAVER!C44 -> 353365 | E32: =E33/(OEM!E38/OEM!E37) -> 1495.7588 | F32: =AWM!D72 -> 53.247483 | G32: =Haver!N42 -> 114.26667 | H32: =UK_HAVER!E44 -> #N/A | I32: =reconstruct_levels_ch!D32 -> 21.244332 | J32: =AWM!C72 -> 8.4902365 | K32: =Haver!H42 -> 7.3125 | L32: =UK_HAVER!D44 -> 9.4966667 | M32: =M33/(OEM_aux!B38/OEM_aux!B37) -> 8.215301 | N32: =Haver!J42 -> 0.88626292 | O32: =1/UK_HAVER!F44 -> 0.61814885 | P32: =1/ '[2]Exchange rate'!$C37 -> 0.010120805 | R32: =Haver!R42 -> 19.05 | S32: =Mater_Q!B33 -> 6.4276667
A33: 32112 | B33: =AWM!B73 -> 1785825.7 | C33: =Haver!D43 -> 2329.8 | D33: =UK_HAVER!C45 -> 357439 | E33: =E34/(OEM!E39/OEM!E38) -> 1528.3625 | F33: =AWM!D73 -> 53.521776 | G33: =Haver!N43 -> 115.33333 | H33: =UK_HAVER!E45 -> #N/A | I33: =reconstruct_levels_ch!D33 -> 21.837013 | J33: =AWM!C73 -> 8.4260121 | K33: =Haver!H43 -> 6.8125 | L33: =UK_HAVER!D45 -> 9.0266667 | M33: =M34/(OEM_aux!B39/OEM_aux!B38) -> 8.215301 | N33: =Haver!J43 -> 0.8235039 | O33: =1/UK_HAVER!F45 -> 0.56967073 | P33: =1/ '[2]Exchange rate'!$C38 -> 0.010350157 | R33: =Haver!R43 -> 17.863333 | S33: =Mater_Q!B34 -> 6.5503333
A34: 32203 | B34: =AWM!B74 -> 1795687 | C34: =Haver!D44 -> 2341.9 | D34: =UK_HAVER!C46 -> 363267 | E34: =E35/(OEM!E40/OEM!E39) -> 1586.3484 | F34: =AWM!D74 -> 53.896274 | G34: =Haver!N44 -> 116.23333 | H34: =UK_HAVER!E46 -> 48.806511 | I34: =reconstruct_levels_ch!D34 -> 22.669605 | J34: =AWM!C74 -> 7.4535992 | K34: =Haver!H44 -> 6.75 | L34: =UK_HAVER!D46 -> 8.6333333 | M34: =M35/(OEM_aux!B40/OEM_aux!B39) -> 8.215301 | N34: =Haver!J44 -> 0.81052822 | O34: =1/UK_HAVER!F46 -> 0.5563695 | P34: =1/ '[2]Exchange rate'!$C39 -> 0.010377788 | R34: =Haver!R44 -> 15.736667 | S34: =Mater_Q!B35 -> 6.319
A35: 32295 | B35: =AWM!B75 -> 1812194.3 | C35: =Haver!D45 -> 2372.7 | D35: =UK_HAVER!C47 -> 365209 | E35: =E36/(OEM!E41/OEM!E40) -> 1628.4838 | F35: =AWM!D75 -> 54.28582 | G35: =Haver!N45 -> 117.56667 | H35: =UK_HAVER!E47 -> 49.226184 | I35: =reconstruct_levels_ch!D35 -> 23.91408 | J35: =AWM!C75 -> 7.2598364 | K35: =Haver!H45 -> 7.4375 | L35: =UK_HAVER!D47 -> 7.9533333 | M35: =M36/(OEM_aux!B41/OEM_aux!B40) -> 8.215301 | N35: =Haver!J45 -> 0.82118886 | O35: =1/UK_HAVER!F47 -> 0.54303557 | P35: =1/ '[2]Exchange rate'!$C40 -> 0.010308164 | R35: =Haver!R45 -> 16.15 | S35: =Mater_Q!B36 -> 6.4906667
A36: 32387 | B36: =AWM!B76 -> 1834640.2 | C36: =Haver!D46 -> 2386.6 | D36: =UK_HAVER!C48 -> 369774 | E36: =E37/(OEM!E42/OEM!E41) -> 1662.1782 | F36: =AWM!D76 -> 54.701298 | G36: =Haver!N46 -> 119 | H36: =UK_HAVER!E48 -> 49.862458 | I36: =reconstruct_levels_ch!D36 -> 26.066443 | J36: =AWM!C76 -> 7.9743925 | K36: =Haver!H46 -> 8.125 | L36: =UK_HAVER!D48 -> 10.89 | M36: =M37/(OEM_aux!B42/OEM_aux!B41) -> 8.6812937 | N36: =Haver!J46 -> 0.89768756 | O36: =1/UK_HAVER!F48 -> 0.5899009 | P36: =1/ '[2]Exchange rate'!$C41 -> 0.0098432947 | R36: =Haver!R46 -> 14.326667 | S36: =Mater_Q!B37 -> 6.7166667
A37: 32478 | B37: =AWM!B77 -> 1851607.8 | C37: =Haver!D47 -> 2418.4 | D37: =UK_HAVER!C49 -> 372752 | E37: =E38/(OEM!E43/OEM!E42) -> 1695.8015 | F37: =AWM!D77 -> 55.123779 | G37: =Haver!N47 -> 120.3 | H37: =UK_HAVER!E49 -> 50.533578 | I37: =reconstruct_levels_ch!D37 -> 27.756886 | J37: =AWM!C77 -> 8.4754225 | K37: =Haver!H47 -> 8.6875 | L37: =UK_HAVER!D49 -> 12.273333 | M37: =M38/(OEM_aux!B43/OEM_aux!B42) -> 9.6132828 | N37: =Haver!J47 -> 0.85469355 | O37: =1/UK_HAVER!F49 -> 0.5583369 | P37: =1/ '[2]Exchange rate'!$C42 -> 0.0099897805 | R37: =Haver!R47 -> 13.58 | S37: =Mater_Q!B38 -> 6.4266667
A38: 32568 | B38: =AWM!B78 -> 1873357.3 | C38: =Haver!D48 -> 2442.9 | D38: =UK_HAVER!C50 -> 374612 | E38: =E39/(OEM!E44/OEM!E43) -> 1656.5506 | F38: =AWM!D78 -> 55.831041 | G38: =Haver!N48 -> 121.66667 | H38: =UK_HAVER!E50 -> 51.259161 | I38: =reconstruct_levels_ch!D38 -> 29.027599 | J38: =AWM!C78 -> 9.5159466 | K38: =Haver!H48 -> 9.75 | L38: =UK_HAVER!D50 -> 12.88 | M38: =M39/(OEM_aux!B44/OEM_aux!B43) -> 11.63259 | N38: =Haver!J48 -> 0.88794175 | O38: =1/UK_HAVER!F50 -> 0.57246446 | P38: =1/ '[2]Exchange rate'!$C43 -> 0.0097782871 | R38: =Haver!R48 -> 17.586667 | S38: =Mater_Q!B39 -> 6.8013333
A39: 32660 | B39: =AWM!B79 -> 1891166.5 | C39: =Haver!D49 -> 2461.6 | D39: =UK_HAVER!C51 -> 376951 | E39: =E40/(OEM!E45/OEM!E44) -> 1697.6319 | F39: =AWM!D79 -> 56.474651 | G39: =Haver!N49 -> 123.63333 | H39: =UK_HAVER!E51 -> 51.840861 | I39: =reconstruct_levels_ch!D39 -> 29.809874 | J39: =AWM!C79 -> 9.6913451 | K39: =Haver!H49 -> 9.5625 | L39: =UK_HAVER!D51 -> 13.223333 | M39: =M40/(OEM_aux!B45/OEM_aux!B44) -> 12.642242 | N39: =Haver!J49 -> 0.93001916 | O39: =1/UK_HAVER!F51 -> 0.61418774 | P39: =1/ '[2]Exchange rate'!$C44 -> 0.0094009613 | R39: =Haver!R49 -> 18.873333 | S39: =Mater_Q!B40 -> 6.864
... A41: 32843 | B41: =AWM!B81 -> 1922300 | C41: =Haver!D51 -> 2484.7 | D41: =UK_HAVER!C53 -> 377508 | E41: =E42/(OEM!E47/OEM!E46) -> 1768.0902 | F41: =AWM!D81 -> 57.387609 | G41: =Haver!N51 -> 125.86667 | H41: =UK_HAVER!E53 -> 53.331518 | I41: =reconstruct_levels_ch!D41 -> 29.838444 | J41: =AWM!C81 -> 11.071902 | K41: =Haver!H51 -> 8.25 | L41: =UK_HAVER!D53 -> 14.81 | M41: =M42/(OEM_aux!B47/OEM_aux!B46) -> 12.642242 | N41: =Haver!J51 -> 0.88523255 | O41: =1/UK_HAVER!F53 -> 0.63071586 | P41: =1/ '[2]Exchange rate'!$C46 -> 0.0093827466 | R41: =Haver!R51 -> 19.16 | S41: =Mater_Q!B42 -> 7.1713333
...

Sheet Haver
C1: EZGDP | D1: USGDP | E1: CHGDP | F1: CHGDP | G1: EZRR | H1: USRR | I1: CHRR | J1: USDEUR | K1: USDCNY | L1: EURCNY | M1: EZCPI | N1: USCPI | O1: CHCPI | P1: CHCPI | Q1: VIX | R1: poil brent | S1: poil wti | T1: EZ10Y
A2: 19801 *Q | B2: .excel_last | C2: J025GDPT@EUDATA | D2: S111NGPC@G10 | E2: H924NGPC@EMERGE | F2: SA(DIFF%(H924NGPC@EMERGE)) | G2: N023RTAR@G10 | H2: N111RTAU@G10 | I2: N924RTAR@EMERGE | J2: 1/(X111EXR@EUDATA) | K2: FXCHI@USECON | L2: X924EXR@EUDATA | M2: P023SH@EUDATA | N2: S111PC@G10 | O2: H924PC@EMERGE | P2: SA(DIFF%(H924PC@EMERGE)) | Q2: SPVIX@USECON | R2: N112POIL@G10 | S2: N111POIL@G10 | T2: I023R@EUDATA
A3: .DESC | C3: EA21: Gross Domestic Product (SWDA, Mil.Ch.2020.EUR) | D3: U.S.: Gross Domestic Product (SA, Bil.Chn.2017$) | E3: China: Gross Domestic Product (SA, Bil.2020.Yuan) | F3: China: Gross Domestic Product (SA, 2020.Yuan) | G3: Euro Area 11-21: Deposit Rate (EOP, %) | H3: U.S.: Federal Open Market Committee: Fed Funds Target Rate: Upper Limit (EOP, %) | I3: China: Loan Prime Rate: 1 Year (EOP, %) | J3: Euro Exchange Rate: United States Dollar (Avg, USD/EUR) | K3: Foreign Exchange Rate: People's Republic of China (Yuan/US$) | L3: Euro Exchange Rate: Chinese Yuan Renminbi (Avg, Yuan/Euro) | M3: EA11-20: HICP DISC(SWDA, 2015=100) | N3: U.S.: Consumer Price Index (SA, 1982-84=100) | O3: China: Consumer Price Index (SA, 2025=100) | P3: China: Consumer Price Index (SA, 2025=100) | Q3: CBOE Market Volatility Index: VIX (Index) | R3: European Brent Spot Price FOB ($/Barrel) | S3: U.S.: Spot Oil Price: West Texas Intermediate [Prior'82=Posted Price] ($/Barrel) | T3: Euro Area 11-21: Long Term Government Bond Yield: Rolling 12 Month Average (%)
A4: .T1 | C4: Q1-1995 | D4: Q1-1947 | E4: Q1-1992 | F4: Q1-1992 | G4: Q1-1999 <- Jan-1999 | H4: Q3-1982 <- Sep-1982 | I4: Q4-2013 <- Oct-2013 | J4: Q1-1971 <- Jan-1971 | K4: Q1-1970 <- Jan-1970 | L4: Q1-2000 <- Jan-2000 | M4: Q1-1997 <- Jan-1997 | N4: Q1-1947 <- Jan-1947 | O4: Q1-1984 <- Jan-1984 | P4: Q1-1984 <- Jan-1984 | Q4: Q1-1990 <- Jan-1990 | R4: Q2-1986 <- Jun-1986 | S4: Q1-1946 <- Jan-1946 | T4: Q4-1991 <- Nov-1991
A5: .TN | C5: Q1-2026 | D5: Q1-2026 | E5: Q1-2026 | F5: Q1-2026 | G5: Q1-2026 <- May-2026 | H5: Q1-2026 <- May-2026 | I5: Q1-2026 <- May-2026 | J5: Q1-2026 <- May-2026 | K5: Q1-2026 <- May-2026 | L5: Q1-2026 <- May-2026 | M5: Q4-2025 <- Dec-2025 | N5: Q1-2026 <- Apr-2026 | O5: Q1-2026 <- Apr-2026 | P5: Q1-2026 <- Apr-2026 | Q5: Q1-2026 <- May-2026 | R5: Q1-2026 <- May-2026 | S5: Q1-2026 <- May-2026 | T5: Q1-2026 <- Apr-2026
A6: .SOURCE | C6: Eurostat | D6: BEA | E6: CNBS | F6: CNBS | G6: ECB | H6: FRB | I6: PBoC | J6: ECB | K6: FRB | L6: ECB | M6: DISC | N6: BLS | O6: CNBS/H | P6: CNBS/H | Q6: CBOE | R6: EIA | S6: WSJ | T6: ECB
A7: .LSOURCE | C7: Statistical Office of the European Communities | D7: Bureau of Economic Analysis | E7: China National Bureau of Statistics | F7: China National Bureau of Statistics | G7: European Central Bank | H7: Federal Reserve Board | I7: People's Bank of China | J7: European Central Bank | K7: Federal Reserve Board | L7: European Central Bank | M7: Discontinued | N7: Bureau of Labor Statistics | O7: China National Bureau of Statistics/Haver Analytics | P7: China National Bureau of Statistics/Haver Analytics | Q7: Chicago Board Options Exchange | R7: Energy Information Administration | S7: Wall Street Journal | T7: European Central Bank
A8: .AGG | C8: Sum | D8: Sum | E8: Sum | F8: Sum | G8: End of Period | H8: End of Period | I8: End of Period | J8: Average | K8: Average | L8: Average | M8: Average | N8: Average | O8: Average | P8: Average | Q8: Average | R8: Average | S8: Average | T8: Average
A9: .FRQ | C9: Quarterly | D9: Quarterly | E9: Quarterly | F9: Quarterly | G9: Quarterly <- Monthly | H9: Quarterly <- Monthly | I9: Quarterly <- Monthly | J9: Quarterly <- Monthly | K9: Quarterly <- Monthly | L9: Quarterly <- Monthly | M9: Quarterly <- Monthly | N9: Quarterly <- Monthly | O9: Quarterly <- Monthly | P9: Quarterly <- Monthly | Q9: Quarterly <- Monthly | R9: Quarterly <- Monthly | S9: Quarterly <- Monthly | T9: Quarterly <- Monthly
A10: .MAG | C10: 6 | D10: 9 | E10: 9 | F10: 0 <- 9 | G10: 0 | H10: 0 | I10: 0 | J10: 0 | K10: 0 | L10: 0 | M10: 0 | N10: 0 | O10: 0 | P10: 0 | Q10: 0 | R10: 0 | S10: 0 | T10: 0
A11: .GEO2 | C11: Not Defined | D11: Not Defined | E11: Not Defined | F11: Not Defined | G11: Not Defined | H11: Not Defined | I11: Not Defined | J11: 023 | K11: 111 | L11: 023 | M11: Not Defined | N11: Not Defined | O11: Not Defined | P11: Not Defined | Q11: Not Defined | R11: Not Defined | S11: Not Defined | T11: Not Defined
A12: 19801 | B12: 29311 | C12: #N/A | D12: 1835.4 | E12: #N/A | F12: #N/A | G12: #N/A | H12: #N/A | I12: #N/A | J12: 0.70891484 | K12: 1.5151333 | L12: #N/A | M12: #N/A | N12: 79.033333 | O12: #N/A | P12: #N/A | Q12: #N/A | R12: #N/A | S12: 35.833333 | T12: #N/A
A13: 19802 | B13: 29402 | C13: #N/A | D13: 1797.6 | E13: #N/A | F13: #N/A | G13: #N/A | H13: #N/A | I13: #N/A | J13: 0.71904683 | K13: 1.5008333 | L13: #N/A | M13: #N/A | N13: 81.7 | O13: #N/A | P13: #N/A | Q13: #N/A | R13: #N/A | S13: 39.5 | T13: #N/A
A14: 19803 | B14: 29494 | C14: #N/A | D14: 1795.4 | E14: #N/A | F14: #N/A | G14: #N/A | H14: #N/A | I14: #N/A | J14: 0.70283289 | K14: 1.4644 | L14: #N/A | M14: #N/A | N14: 83.233333 | O14: #N/A | P14: #N/A | Q14: #N/A | R14: #N/A | S14: 37.833333 | T14: #N/A
A15: 19804 | B15: 29586 | C15: #N/A | D15: 1828.9 | E15: #N/A | F15: #N/A | G15: #N/A | H15: #N/A | I15: #N/A | J15: 0.74632621 | K15: 1.5131667 | L15: #N/A | M15: #N/A | N15: 85.566667 | O15: #N/A | P15: #N/A | Q15: #N/A | R15: #N/A | S15: 36.333333 | T15: #N/A
A16: 19811 | B16: 29676 | C16: #N/A | D16: 1864.8 | E16: #N/A | F16: #N/A | G16: #N/A | H16: #N/A | I16: #N/A | J16: 0.81110895 | K16: 1.5987667 | L16: #N/A | M16: #N/A | N16: 87.933333 | O16: #N/A | P16: #N/A | Q16: #N/A | R16: #N/A | S16: 38 | T16: #N/A
A17: 19812 | B17: 29767 | C17: #N/A | D17: 1850.9 | E17: #N/A | F17: #N/A | G17: #N/A | H17: #N/A | I17: #N/A | J17: 0.89624206 | K17: 1.7178333 | L17: #N/A | M17: #N/A | N17: 89.766667 | O17: #N/A | P17: #N/A | Q17: #N/A | R17: #N/A | S17: 37.333333 | T17: #N/A
A18: 19813 | B18: 29859 | C18: #N/A | D18: 1873.1 | E18: #N/A | F18: #N/A | G18: #N/A | H18: #N/A | I18: #N/A | J18: 0.96849799 | K18: 1.7730667 | L18: #N/A | M18: #N/A | N18: 92.266667 | O18: #N/A | P18: #N/A | Q18: #N/A | R18: #N/A | S18: 36 | T18: #N/A
A19: 19814 | B19: 29951 | C19: #N/A | D19: 1852.7 | E19: #N/A | F19: #N/A | G19: #N/A | H19: #N/A | I19: #N/A | J19: 0.91801513 | K19: 1.7463333 | L19: #N/A | M19: #N/A | N19: 93.766667 | O19: #N/A | P19: #N/A | Q19: #N/A | R19: #N/A | S19: 35.333333 | T19: #N/A
A20: 19821 | B20: 30041 | C20: #N/A | D20: 1823.9 | E20: #N/A | F20: #N/A | G20: #N/A | H20: #N/A | I20: #N/A | J20: 0.96385852 | K20: 1.8114 | L20: #N/A | M20: #N/A | N20: 94.6 | O20: #N/A | P20: #N/A | Q20: #N/A | R20: #N/A | S20: 31.296667 | T20: #N/A
A21: 19822 | B21: 30132 | C21: #N/A | D21: 1832.2 | E21: #N/A | F21: #N/A | G21: #N/A | H21: #N/A | I21: #N/A | J21: 0.99683737 | K21: 1.8567333 | L21: #N/A | M21: #N/A | N21: 95.966667 | O21: #N/A | P21: #N/A | Q21: #N/A | R21: #N/A | S21: 34.816667 | T21: #N/A
A22: 19823 | B22: 30224 | C22: #N/A | D22: 1825.2 | E22: #N/A | F22: #N/A | G22: #N/A | H22: 10.25 | I22: #N/A | J22: 1.0519222 | K22: 1.9433 | L22: #N/A | M22: #N/A | N22: 97.633333 | O22: #N/A | P22: #N/A | Q22: #N/A | R22: #N/A | S22: 34.58 | T22: #N/A
A23: 19824 | B23: 30316 | C23: #N/A | D23: 1826 | E23: #N/A | F23: #N/A | G23: #N/A | H23: 8.5 | I23: #N/A | J23: 1.0711849 | K23: 1.9778 | L23: #N/A | M23: #N/A | N23: 97.933333 | O23: #N/A | P23: #N/A | Q23: #N/A | R23: #N/A | S23: 33.85 | T23: #N/A
A24: 19831 | B24: 30406 | C24: #N/A | D24: 1850 | E24: #N/A | F24: #N/A | G24: #N/A | H24: 8.625 | I24: #N/A | J24: 1.0548208 | K24: 1.9575 | L24: #N/A | M24: #N/A | N24: 98 | O24: #N/A | P24: #N/A | Q24: #N/A | R24: #N/A | S24: 29.653333 | T24: #N/A
A25: 19832 | B25: 30497 | C25: #N/A | D25: 1892.1 | E25: #N/A | F25: #N/A | G25: #N/A | H25: 9 | I25: #N/A | J25: 1.0964135 | K25: 1.9927333 | L25: #N/A | M25: #N/A | N25: 99.133333 | O25: #N/A | P25: #N/A | Q25: #N/A | R25: #N/A | S25: 30.536667 | T25: #N/A
A26: 19833 | B26: 30589 | C26: #N/A | D26: 1929.9 | E26: #N/A | F26: #N/A | G26: #N/A | H26: 9.375 | I26: #N/A | J26: 1.1613215 | K26: 1.9892 | L26: #N/A | M26: #N/A | N26: 100.1 | O26: #N/A | P26: #N/A | Q26: #N/A | R26: #N/A | S26: 31.56 | T26: #N/A
A27: 19834 | B27: 30681 | C27: #N/A | D27: 1970.2 | E27: #N/A | F27: #N/A | G27: #N/A | H27: 9.375 | I27: #N/A | J27: 1.1850185 | K27: 1.9841333 | L27: #N/A | M27: #N/A | N27: 101.1 | O27: #N/A | P27: #N/A | Q27: #N/A | R27: #N/A | S27: 29.83 | T27: #N/A
A28: 19841 | B28: 30772 | C28: #N/A | D28: 2008.7 | E28: #N/A | F28: #N/A | G28: #N/A | H28: 10.5 | I28: #N/A | J28: 1.2024318 | K28: 2.0588 | L28: #N/A | M28: #N/A | N28: 102.53333 | O28: 16.84 | P28: #N/A | Q28: #N/A | R28: #N/A | S28: 30.198667 | T28: #N/A
A29: 19842 | B29: 30863 | C29: #N/A | D29: 2043.4 | E29: #N/A | F29: #N/A | G29: #N/A | H29: 10.5 | I29: #N/A | J29: 1.2116977 | K29: 2.1657667 | L29: #N/A | M29: #N/A | N29: 103.5 | O29: 16.95 | P29: 0.0067228861 | Q29: #N/A | R29: #N/A | S29: 30.368333 | T29: #N/A
A30: 19843 | B30: 30955 | C30: #N/A | D30: 2063.1 | E30: #N/A | F30: #N/A | G30: #N/A | H30: 11 | I30: #N/A | J30: 1.3025972 | K30: 2.4061 | L30: #N/A | M30: #N/A | N30: 104.4 | O30: 16.98 | P30: 0.0060729788 | Q30: #N/A | R30: #N/A | S30: 29.104333 | T30: #N/A
A31: 19844 | B31: 31047 | C31: #N/A | D31: 2080.1 | E31: #N/A | F31: #N/A | G31: #N/A | H31: 8.125 | I31: #N/A | J31: 1.3673007 | K31: 2.7075333 | L31: #N/A | M31: #N/A | N31: 105.3 | O31: 17.136667 | P31: 0.0090100711 | Q31: #N/A | R31: #N/A | S31: 27.430667 | T31: #N/A
A32: 19851 | B32: 31137 | C32: #N/A | D32: 2100.2 | E32: #N/A | F32: #N/A | G32: #N/A | H32: 8.5 | I32: #N/A | J32: 1.4618729 | K32: 2.8346667 | L32: #N/A | M32: #N/A | N32: 106.26667 | O32: 17.91 | P32: 0.040991062 | Q32: #N/A | R32: #N/A | S32: 27.05 | T32: #N/A
A33: 19852 | B33: 31228 | C33: #N/A | D33: 2118.7 | E33: #N/A | F33: #N/A | G33: #N/A | H33: 7.75 | I33: #N/A | J33: 1.3773757 | K33: 2.8576333 | L33: #N/A | M33: #N/A | N33: 107.23333 | O33: 18.53 | P33: 0.034841861 | Q33: #N/A | R33: #N/A | S33: 27.857 | T33: #N/A
A34: 19853 | B34: 31320 | C34: #N/A | D34: 2151.1 | E34: #N/A | F34: #N/A | G34: #N/A | H34: 8 | I34: #N/A | J34: 1.2739995 | K34: 2.9208 | L34: #N/A | M34: #N/A | N34: 107.9 | O34: 18.876667 | P34: 0.022633036 | Q34: #N/A | R34: #N/A | S34: 27.791 | T34: #N/A
A35: 19854 | B35: 31412 | C35: #N/A | D35: 2167.1 | E35: #N/A | F35: #N/A | G35: #N/A | H35: 7.75 | I35: #N/A | J35: 1.1713136 | K35: 3.1654333 | L35: #N/A | M35: #N/A | N35: 109 | O35: 19.063333 | P35: 0.0095166401 | Q35: #N/A | R35: #N/A | S35: 29.193 | T35: #N/A
A36: 19861 | B36: 31502 | C36: #N/A | D36: 2187.3 | E36: #N/A | F36: #N/A | G36: #N/A | H36: 7.25 | I36: #N/A | J36: 1.0817094 | K36: 3.2149667 | L36: #N/A | M36: #N/A | N36: 109.56667 | O36: 19.356667 | P36: 0.012038091 | Q36: #N/A | R36: #N/A | S36: 17.001667 | T36: #N/A
A37: 19862 | B37: 31593 | C37: #N/A | D37: 2197.1 | E37: #N/A | F37: #N/A | G37: #N/A | H37: 6.875 | I37: #N/A | J37: 1.0427982 | K37: 3.2090667 | L37: #N/A | M37: #N/A | N37: 109.03333 | O37: 19.406667 | P37: 0.0027180194 | Q37: #N/A | R37: #N/A | S37: 13.92 | T37: #N/A
A38: 19863 | B38: 31685 | C38: #N/A | D38: 2218.2 | E38: #N/A | F38: #N/A | G38: #N/A | H38: 5.875 | I38: #N/A | J38: 0.98696515 | K38: 3.6904667 | L38: #N/A | M38: #N/A | N38: 109.7 | O38: 19.66 | P38: 0.016208381 | Q38: #N/A | R38: 12.316667 | S38: 13.86 | T38: #N/A
A39: 19864 | B39: 31777 | C39: #N/A | D39: 2230.1 | E39: #N/A | F39: #N/A | G39: #N/A | H39: 5.875 | I39: #N/A | J39: 0.96334164 | K39: 3.7295 | L39: #N/A | M39: #N/A | N39: 110.46667 | O39: 20.15 | P39: 0.024416901 | Q39: #N/A | R39: 14.676667 | S39: 15.378333 | T39: #N/A
A40: 19871 | B40: 31867 | C40: #N/A | D40: 2246.6 | E40: #N/A | F40: #N/A | G40: #N/A | H40: 6 | I40: #N/A | J40: 0.88926304 | K40: 3.7314 | L40: #N/A | M40: #N/A | N40: 111.8 | O40: 20.446667 | P40: 0.012528852 | Q40: #N/A | R40: 17.87 | S40: 18.229 | T40: #N/A
...

Sheet Haver_M
C1: USCPI
A2: 198001 *M | B2: .excel_last | C2: S111PC@G10
A3: .DESC | C3: U.S.: Consumer Price Index (SA, 1982-84=100)
A4: .T1 | C4: Jan-1947
A5: .TN | C5: Apr-2026
A6: .SOURCE | C6: BLS
A7: .LSOURCE | C7: Bureau of Labor Statistics
A8: .AGG | C8: Average
A9: .FRQ | C9: Monthly
A10: .MAG | C10: 0
A11: .GEO2 | C11: Not Defined
A12: 198001 | B12: 29251 | C12: 78
A13: 198002 | B13: 29280 | C13: 79
A14: 198003 | B14: 29311 | C14: 80.1
A15: 198004 | B15: 29341 | C15: 80.9
A16: 198005 | B16: 29372 | C16: 81.7
A17: 198006 | B17: 29402 | C17: 82.5
A18: 198007 | B18: 29433 | C18: 82.6
A19: 198008 | B19: 29464 | C19: 83.2
A20: 198009 | B20: 29494 | C20: 83.9
A21: 198010 | B21: 29525 | C21: 84.7
A22: 198011 | B22: 29555 | C22: 85.6
A23: 198012 | B23: 29586 | C23: 86.4
... A560: 202509 | B560: 45930 | C560: 324.245
A561: 202510 | B561: 45961 | C561: #N/A
A562: 202511 | B562: 45991 | C562: 325.063
A563: 202512 | B563: 46022 | C563: 326.031 | D563: =AVERAGE(C562:C563) -> 325.547
A564: 202601 | B564: 46053 | C564: 326.588
A565: 202602 | B565: 46081 | C565: 327.46
A566: 202603 | B566: 46112 | C566: 330.293
A567: 202604 | B567: 46142 | C567: 332.407
A568: 202605 | B568: 46173 | C568: #N/A

Sheet OEM
A1: Location | B1: China | C1: Eurozone | D1: United States | E1: China | F1: Eurozone | G1: United States | H1: China
A2: Indicator | B2: Interest rate, central bank policy | C2: Interest rate, central bank policy | D2: Interest rate, central bank policy | E2: GDP, real, seasonally adjusted, LCU | F2: GDP, real, seasonally adjusted, LCU | G2: GDP, real, seasonally adjusted, LCU | H2: Consumer price index
A3: Scenario | B3: Sep25_2 25yr | C3: Sep25_2 25yr | D3: Sep25_2 25yr | E3: Sep25_2 25yr | F3: Sep25_2 25yr | G3: Sep25_2 25yr | H3: Sep25_2 25yr
A4: Units | B4: % | C4: % | D4: % | E4: Yuan | F4: Euro | G4: US$ | H4: Index
A5: Scale | B5: NA | C5: NA | D5: NA | E5: Billions | F5: Billions | G5: Billions | H5: NA
A6: Measurement | B6: Level | C6: Level | D6: Level | E6: Level | F6: Level | G6: Level | H6: Level
A7: 1980 Q1 | B7: 0.001 | C7: 0.001 | D7: 13.93896 | E7: 719.647 | F7: 1561.599 | G7: 1835.4 | H7: 16.1549
A8: 1980 Q2 | B8: 0.001 | C8: 0.001 | D8: 11.7426 | E8: 734.2954 | F8: 1554.268 | G8: 1797.575 | H8: 16.2807
A9: 1980 Q3 | B9: 0.001 | C9: 0.001 | D9: 9.094363 | E9: 748.4635 | F9: 1553.382 | G9: 1795.425 | H9: 15.72297
A10: 1980 Q4 | B10: 0.001 | C10: 0.001 | D10: 14.72999 | E10: 764.0247 | F10: 1554.111 | G10: 1828.925 | H10: 15.98073
A11: 1981 Q1 | B11: 0.001 | C11: 0.001 | D11: 15.40231 | E11: 754.6949 | F11: 1555.611 | G11: 1864.75 | H11: 16.55324
A12: 1981 Q2 | B12: 0.001 | C12: 0.001 | D12: 16.51873 | E12: 771.1904 | F12: 1560.27 | G12: 1850.925 | H12: 16.68214
A13: 1981 Q3 | B13: 0.001 | C13: 0.001 | D13: 16.47078 | E13: 787.2404 | F13: 1564.575 | G13: 1873.1 | H13: 16.11065
A14: 1981 Q4 | B14: 0.001 | C14: 0.001 | D14: 12.66561 | E14: 804.7195 | F14: 1568.246 | G14: 1852.7 | H14: 16.37477
A15: 1982 Q1 | B15: 0.001 | C15: 0.001 | D15: 13.27632 | E15: 820.2949 | F15: 1574.728 | G15: 1823.9 | H15: 16.87782
A16: 1982 Q2 | B16: 0.001 | C16: 0.001 | D16: 13.51189 | E16: 839.2487 | F16: 1576.846 | G16: 1832.225 | H16: 17.00924
A17: 1982 Q3 | B17: 0.001 | C17: 0.001 | D17: 10.25 | E17: 859.0854 | F17: 1568.435 | G17: 1825.225 | H17: 16.42655
A18: 1982 Q4 | B18: 0.001 | C18: 0.001 | D18: 9.189394 | E18: 879.734 | F18: 1569.108 | G18: 1825.95 | H18: 16.69584
... A230: 2035 Q4 | B230: 1.199933 | C230: 2.149925 | D230: 3.124914 | E230: 47612.21 | F230: 3694.99 | G230: 7294.975 | H230: 115.9576
A231: Source | B231: People's Bank of China / Haver Analytics | C231: European Central Bank \Haver Analytics | D231: Federal Reserve Board \Haver Analytics | E231: China National Bureau of Statistics\Haver Analytics | F231: Statistical Office of the European Communities\Euro Area Business Cycle Network\Haver Analytics | G231: Bureau of Economic Analysis\Haver Analytics | H231: China National Bureau of Statistics\Haver Analytics
A232: Seasonally adjusted | B232: FALSE | C232: FALSE | D232: FALSE | E232: TRUE | F232: TRUE | G232: TRUE | H232: FALSE
A233: Base year price | B233: NA | C233: NA | D233: NA | E233: 2020 | F233: chained 2020 | G233: chained 2017 | H233: NA
A234: Base year index | B234: NA | C234: NA | D234: NA | E234: NA | F234: NA | G234: NA | H234: 2020
A235: Historical end year | B235: 2025 | C235: 2025 | D235: 2025 | E235: 2025 | F235: 2025 | G235: 2025 | H235: 2025
A236: Historical end quarter | B236: 2 | C236: 2 | D236: 2 | E236: 2 | F236: 2 | G236: 2 | H236: 2
A237: Date of last update | B237: NA | C237: NA | D237: NA | E237: NA | F237: NA | G237: NA | H237: NA
A238: Source details | B238: R9247DL@INTDAILY | C238: agg(R023RM@INTDAILY,avg), spliced with I023M@EUDATA pre-1999 | D238: FFEDTAR@DAILY | E238: GDP, real, LCU (Seasonally adjusted by Oxford Economics) | F238: J025GDPU@EUDATA/1000 | G238: GDPH@USNA / 4 | H238: 2020=100, grown by N924PCY@EMERGEPR
A239: Additional source details | B239: China: PBoC OMO:7 Days Reverse Repurchase: Reference Yield (%p.a.) | C239: Euro-Area: Main Refinancing Operation on Effective Date (%) | D239: Effective federal funds rate prior to 1982Q4; Federal funds target rate or mid-point from 1982Q4 (H.15 Item 1) | E239: NA | F239: EA19: Gross Domestic Product (SWDA, Mil.Ch.2020.EUR-ECU) /1000 | G239: Real Gross Domestic Product (SAAR, Bil.Chn.2017$) / 4 | H239: 2020=100 grown by China: Consumer Price Index (NSA, year/year % chg)
A240: Location code | B240: CHINA | C240: EURO_11 | D240: US | E240: CHINA | F240: EURO_11 | G240: US | H240: CHINA
A241: Indicator code | B241: RCB | C241: RCB | D241: RCB | E241: GDPSA | F241: GDPSA | G241: GDPSA | H241: CPI
A242: Databank code | B242: /oxford-economics/releases/GEM/Sep25_2 25yr | C242: /oxford-economics/releases/GEM/Sep25_2 25yr | D242: /oxford-economics/releases/GEM/Sep25_2 25yr | E242: /oxford-economics/releases/GEM/Sep25_2 25yr | F242: /oxford-economics/releases/GEM/Sep25_2 25yr | G242: /oxford-economics/releases/GEM/Sep25_2 25yr | H242: /oxford-economics/releases/GEM/Sep25_2 25yr

Sheet OEM_aux
A1: Location | B1: China | C1: China
A2: Indicator | B2: Interest rate, central bank policy | C2: Exchange rate, period average, per Euro
A3: Scenario | B3: Jul25_2 25yr | C3: Jul25_2 25yr
A4: Units | B4: % | C4: Yuan per Euro
A5: Scale | B5: NA | C5: NA
A6: Measurement | B6: Level | C6: Level
A7: 1980 Q1 | B7: 3.466667 | C7: 2.137539
A8: 1980 Q2 | B8: 3.466667 | C8: 2.087486
A9: 1980 Q3 | B9: 3.466667 | C9: 2.083947
A10: 1980 Q4 | B10: 3.466667 | C10: 2.027264
A11: 1981 Q1 | B11: 3.466667 | C11: 1.967676
A12: 1981 Q2 | B12: 3.466667 | C12: 1.913917
A13: 1981 Q3 | B13: 3.466667 | C13: 1.823786
A14: 1981 Q4 | B14: 3.466667 | C14: 1.896846
A15: 1982 Q1 | B15: 5.626667 | C15: 1.875449
A16: 1982 Q2 | B16: 5.626667 | C16: 1.85888
A17: 1982 Q3 | B17: 5.626667 | C17: 1.842025
A18: 1982 Q4 | B18: 5.626667 | C18: 1.840952
... A230: 2035 Q4 | B230: 1.999919 | C230: 7.854873
A231: Source | B231: People's Bank of China\Haver Analytics | C231: Oxford Economics calculation
A232: Seasonally adjusted | B232: FALSE | C232: FALSE
A233: Base year price | B233: NA | C233: NA
A234: Base year index | B234: NA | C234: NA
A235: Historical end year | B235: 2024 | C235: NA
A236: Historical end quarter | B236: 4 | C236: NA
A237: Date of last update | B237: NA | C237: NA
A238: Source details | B238: N924FSY1@EMERGEPR, avg, extended back with RLEND | C238: Exchange rate, period average * Exchange rate, period average, Eurozone
A239: Additional source details | B239: China: Medium Term Lending Facility Rate: One Year | C239: NA
A240: Location code | B240: CHINA | C240: CHINA
A241: Indicator code | B241: RCB | C241: RXEURO
A242: Databank code | B242: /oxford-economics/releases/GEM/Jul25_2 25yr | C242: /oxford-economics/releases/GEM/Jul25_2 25yr

Sheet AWM
A1: date | B1: YER | C1: STN | D1: HICP
A2: 25628 | B2: =[3]AWMD_Updated!B2 -> 1099492.8 | C2: =[3]AWMD_Updated!AI2 -> 7.9869932 | D2: =[3]AWMD_Updated!T2 -> 14.274151
A3: 25720 | B3: =[3]AWMD_Updated!B3 -> 1120627.1 | C3: =[3]AWMD_Updated!AI3 -> 7.956545 | D3: =[3]AWMD_Updated!T3 -> 14.434899
A4: 25812 | B4: =[3]AWMD_Updated!B4 -> 1134128 | C4: =[3]AWMD_Updated!AI4 -> 7.6021888 | D4: =[3]AWMD_Updated!T4 -> 14.568972
A5: 25903 | B5: =[3]AWMD_Updated!B5 -> 1147866.6 | C5: =[3]AWMD_Updated!AI5 -> 7.2423084 | D5: =[3]AWMD_Updated!T5 -> 14.752619
A6: 25993 | B6: =[3]AWMD_Updated!B6 -> 1145859.6 | C6: =[3]AWMD_Updated!AI6 -> 6.5168982 | D6: =[3]AWMD_Updated!T6 -> 15.02285
A7: 26085 | B7: =[3]AWMD_Updated!B7 -> 1160538.2 | C7: =[3]AWMD_Updated!AI7 -> 5.9386375 | D7: =[3]AWMD_Updated!T7 -> 15.276236
A8: 26177 | B8: =[3]AWMD_Updated!B8 -> 1178637.9 | C8: =[3]AWMD_Updated!AI8 -> 6.2262126 | D8: =[3]AWMD_Updated!T8 -> 15.456065
A9: 26268 | B9: =[3]AWMD_Updated!B9 -> 1188012.4 | C9: =[3]AWMD_Updated!AI9 -> 6.0058233 | D9: =[3]AWMD_Updated!T9 -> 15.690365
A10: 26359 | B10: =[3]AWMD_Updated!B10 -> 1205616.5 | C10: =[3]AWMD_Updated!AI10 -> 5.0466009 | D10: =[3]AWMD_Updated!T10 -> 15.955659
A11: 26451 | B11: =[3]AWMD_Updated!B11 -> 1213734.5 | C11: =[3]AWMD_Updated!AI11 -> 4.7536779 | D11: =[3]AWMD_Updated!T11 -> 16.183553
A12: 26543 | B12: =[3]AWMD_Updated!B12 -> 1230330.7 | C12: =[3]AWMD_Updated!AI12 -> 4.8573329 | D12: =[3]AWMD_Updated!T12 -> 16.47098
A13: 26634 | B13: =[3]AWMD_Updated!B13 -> 1248340.6 | C13: =[3]AWMD_Updated!AI13 -> 6.394843 | D13: =[3]AWMD_Updated!T13 -> 16.809797
... A221: 45627 | B221: =[3]AWMD_Updated!B221 -> 3250018.1 | C221: =[3]AWMD_Updated!AI221 -> 2.9964872 | D221: =[3]AWMD_Updated!T221 -> 126.92
A222: 45717 | C222: =[3]AWMD_Updated!AI222 -> 2.6140402 | D222: =[3]AWMD_Updated!T222 -> 127.35333

Sheet Mater_M
B1: EZ10Y_M | C1: EZ10Y_M_Avg
B2: Sovereign 10y (%)
A3: 29221
A4: 29252 | B4: =VLOOKUP($A4,[4]BASE_M!$A:$AZ,MATCH(B$2,[4]BASE_M!$4:$4,0),FALSE) -> 8.394
A5: 29281 | B5: =VLOOKUP($A5,[4]BASE_M!$A:$AZ,MATCH(B$2,[4]BASE_M!$4:$4,0),FALSE) -> 9.372
A6: 29312 | B6: =VLOOKUP($A6,[4]BASE_M!$A:$AZ,MATCH(B$2,[4]BASE_M!$4:$4,0),FALSE) -> 9.36 | C6: =AVERAGE(B4:B6) -> 9.042
A7: 29342 | B7: =VLOOKUP($A7,[4]BASE_M!$A:$AZ,MATCH(B$2,[4]BASE_M!$4:$4,0),FALSE) -> 8.594 | C7: =AVERAGE(B5:B7) -> 9.1086667
A8: 29373 | B8: =VLOOKUP($A8,[4]BASE_M!$A:$AZ,MATCH(B$2,[4]BASE_M!$4:$4,0),FALSE) -> 8.18 | C8: =AVERAGE(B6:B8) -> 8.7113333
A9: 29403 | B9: =VLOOKUP($A9,[4]BASE_M!$A:$AZ,MATCH(B$2,[4]BASE_M!$4:$4,0),FALSE) -> 7.954 | C9: =AVERAGE(B7:B9) -> 8.2426667
A10: 29434 | B10: =VLOOKUP($A10,[4]BASE_M!$A:$AZ,MATCH(B$2,[4]BASE_M!$4:$4,0),FALSE) -> 7.839 | C10: =AVERAGE(B8:B10) -> 7.991
A11: 29465 | B11: =VLOOKUP($A11,[4]BASE_M!$A:$AZ,MATCH(B$2,[4]BASE_M!$4:$4,0),FALSE) -> 8.174 | C11: =AVERAGE(B9:B11) -> 7.989
A12: 29495 | B12: =VLOOKUP($A12,[4]BASE_M!$A:$AZ,MATCH(B$2,[4]BASE_M!$4:$4,0),FALSE) -> 8.361 | C12: =AVERAGE(B10:B12) -> 8.1246667
A13: 29526 | B13: =VLOOKUP($A13,[4]BASE_M!$A:$AZ,MATCH(B$2,[4]BASE_M!$4:$4,0),FALSE) -> 8.704 | C13: =AVERAGE(B11:B13) -> 8.413
A14: 29556 | B14: =VLOOKUP($A14,[4]BASE_M!$A:$AZ,MATCH(B$2,[4]BASE_M!$4:$4,0),FALSE) -> 8.861 | C14: =AVERAGE(B12:B14) -> 8.642
A15: 29587 | B15: =VLOOKUP($A15,[4]BASE_M!$A:$AZ,MATCH(B$2,[4]BASE_M!$4:$4,0),FALSE) -> 8.98 | C15: =AVERAGE(B13:B15) -> 8.8483333
A16: 29618 | B16: =VLOOKUP($A16,[4]BASE_M!$A:$AZ,MATCH(B$2,[4]BASE_M!$4:$4,0),FALSE) -> 9.759 | C16: =AVERAGE(B14:B16) -> 9.2
A17: 29646 | B17: =VLOOKUP($A17,[4]BASE_M!$A:$AZ,MATCH(B$2,[4]BASE_M!$4:$4,0),FALSE) -> 10.084 | C17: =AVERAGE(B15:B17) -> 9.6076667
... A614: 47818 | B614: =VLOOKUP($A614,[4]BASE_M!$A:$AZ,MATCH(B$2,[4]BASE_M!$4:$4,0),FALSE) -> 3.25 | C614: =AVERAGE(B612:B614) -> 3.25

Sheet Mater_Q
B1: EZ10Y
B2: Sovereign 10y (%)
A3: 29281
A4: 29373 | B4: =VLOOKUP($A4,Mater_M!A:AR,3,FALSE) -> 8.7113333
A5: 29465 | B5: =VLOOKUP($A5,Mater_M!A:AR,3,FALSE) -> 7.989
A6: 29556 | B6: =VLOOKUP($A6,Mater_M!A:AR,3,FALSE) -> 8.642
A7: 29646 | B7: =VLOOKUP($A7,Mater_M!A:AR,3,FALSE) -> 9.6076667
A8: 29738 | B8: =VLOOKUP($A8,Mater_M!A:AR,3,FALSE) -> 10.304333
A9: 29830 | B9: =VLOOKUP($A9,Mater_M!A:AR,3,FALSE) -> 10.558667
A10: 29921 | B10: =VLOOKUP($A10,Mater_M!A:AR,3,FALSE) -> 9.9646667
A11: 30011 | B11: =VLOOKUP($A11,Mater_M!A:AR,3,FALSE) -> 9.6733333
A12: 30103 | B12: =VLOOKUP($A12,Mater_M!A:AR,3,FALSE) -> 8.9833333
A13: 30195 | B13: =VLOOKUP($A13,Mater_M!A:AR,3,FALSE) -> 8.9873333
A14: 30286 | B14: =VLOOKUP($A14,Mater_M!A:AR,3,FALSE) -> 8.2193333
A15: 30376 | B15: =VLOOKUP($A15,Mater_M!A:AR,3,FALSE) -> 7.6146667
... A186: 45992 | B186: =VLOOKUP($A186,Mater_M!A:AR,3,FALSE) -> 2.7173333

Sheet SA R
B1: CHCPI OEM | C1: Desestacionalizado con R
A2: 29311 | B2: =OEM!H7 -> 16.1549 | C2: 15.848275
A3: 29402 | B3: =OEM!H8 -> 16.2807 | C3: 15.993708
A4: 29494 | B4: =OEM!H9 -> 15.72297 | C4: 16.095644
A5: 29586 | B5: =OEM!H10 -> 15.98073 | C5: 16.200947
A6: 29676 | B6: =OEM!H11 -> 16.55324 | C6: 16.316586
A7: 29767 | B7: =OEM!H12 -> 16.68214 | C7: 16.325678
A8: 29859 | B8: =OEM!H13 -> 16.11065 | C8: 16.483134
A9: 29951 | B9: =OEM!H14 -> 16.37477 | C9: 16.595976
A10: 30041 | B10: =OEM!H15 -> 16.87782 | C10: 16.60842
A11: 30132 | B11: =OEM!H16 -> 17.00924 | C11: 16.68157
A12: 30224 | B12: =OEM!H17 -> 16.42655 | C12: 16.800222
A13: 30316 | B13: =OEM!H18 -> 16.69584 | C13: 16.923685
... A183: 45838 | B183: =OEM!H188 -> 102.8767 | C183: 103.25252

Sheet UK_HAVER
A1: 801 *Q | B1: .excel_last | C1: ABMIQ@UK | D1: UNBEDR@UK | E1: SA(D7BT@UK) | F1: N112XUSV@G10
A2: .DESC | C2: UK: Real Gross Domestic Product (SA, Mil.Chn.2023.GBP) | D2: UK: Official Bank Rate (Average, %) | E2: UK: Consumer Price Index: All Items (NSA, 2015=100) - Seasonal Adjustment, All | F2: U.K.: Exchange Rate (Avg, US$/Pound)
A3: .T1 | C3: Q1-1955 | D3: Q1-1948 <- Jan-1948 | E3: Q1-1988 <- Jan-1988 | F3: Q1-1947 <- Jan-1947
A4: .TN | C4: Q1-2026 | D4: Q1-2026 <- May-2026 | E4: Q1-2026 <- Apr-2026 | F4: Q1-2026 <- May-2026
A5: .LSOURCE | C5: Office for National Statistics | D5: Bank of England | E5: Office for National Statistics | F5: Federal Reserve Board
A6: .AGG | C6: Sum | D6: Average | E6: Average | F6: Average
A7: .DTLM | C7: May-14-2026 08:16 | D7: Jun-01-2026 14:52 | E7: May-20-2026 08:03 | F7: Jun-01-2026 22:28
A8: .FRQ | C8: Quarterly | D8: Quarterly <- Monthly | E8: Quarterly <- Monthly | F8: Quarterly <- Monthly
A9: .DATA_TYPE | C9: LocCur | D9: % | E9: INDEX | F9: US$/LC
A10: .MAG | C10: 6 | D10: 0 | E10: 0 | F10: 0
A11: .GRP | C11: W31 | D11: P50 | E11: P29 | F11: A04
A12: .GRPDESC | C12: UK: GDP (2nd Release) Press Release, ONS, Quarterly | D12: U.K.: Interbank Rates, BoE, Monthly | E12: UK: Consumer Prices Indexes, ONS, Monthly | F12: U.S.: Spot Exchange Rates, FRB G.5, Monthly
A13: .GEO | C13: 112 | D13: 112 | E13: 112 | F13: 111
A14: 801 | B14: 29311 | C14: 290378 | D14: 17 | E14: #N/A | F14: 2.2525667
A15: 802 | B15: 29402 | C15: 284713 | D15: 17 | E15: #N/A | F15: 2.2824333
A16: 803 | B16: 29494 | C16: 284402 | D16: 16.03 | E16: #N/A | F16: 2.3816
A17: 804 | B17: 29586 | C17: 281496 | D17: 15.2 | E17: #N/A | F17: 2.3855
A18: 811 | B18: 29676 | C18: 281257 | D18: 13.546667 | E18: #N/A | F18: 2.3096333
A19: 812 | B19: 29767 | C19: 282155 | D19: 12 | E19: #N/A | F19: 2.0791667
A20: 813 | B20: 29859 | C20: 285437 | D20: 12.513333 | E20: #N/A | F20: 1.8362
A21: 814 | B21: 29951 | C21: 285814 | D21: 14.61 | E21: #N/A | F21: 1.8821667
A22: 821 | B22: 30041 | C22: 286275 | D22: 13.793333 | E22: #N/A | F22: 1.8461
A23: 822 | B23: 30132 | C23: 289232 | D23: 13.016667 | E23: #N/A | F23: 1.7795667
A24: 823 | B24: 30224 | C24: 289852 | D24: 11.353333 | E24: #N/A | F24: 1.7241333
A25: 824 | B25: 30316 | C25: 291832 | D25: 9.6833333 | E25: #N/A | F25: 1.6481
... A45: 874 | B45: 32142 | C45: 357439 | D45: 9.0266667 | E45: #N/A | F45: 1.7554
A46: 881 | B46: 32233 | C46: 363267 | D46: 8.6333333 | E46: 48.806511 | F46: 1.7973667
A47: 882 | B47: 32324 | C47: 365209 | D47: 7.9533333 | E47: 49.226184 | F47: 1.8415
A48: 883 | B48: 32416 | C48: 369774 | D48: 10.89 | E48: 49.862458 | F48: 1.6952
A49: 884 | B49: 32508 | C49: 372752 | D49: 12.273333 | E49: 50.533578 | F49: 1.7910333
A50: 891 | B50: 32598 | C50: 374612 | D50: 12.88 | E50: 51.259161 | F50: 1.7468333
A51: 892 | B51: 32689 | C51: 376951 | D51: 13.223333 | E51: 51.840861 | F51: 1.6281667
A52: 893 | B52: 32781 | C52: 377573 | D52: 13.76 | E52: 52.427737 | F52: 1.5976667
A53: 894 | B53: 32873 | C53: 377508 | D53: 14.81 | E53: 53.331518 | F53: 1.5855
A54: 901 | B54: 32963 | C54: 379458 | D54: 14.88 | E54: 54.222591 | F54: 1.6572667
A55: 902 | B55: 33054 | C55: 381997 | D55: 14.88 | E55: 55.277047 | F55: 1.6749667
A56: 903 | B56: 33146 | C56: 377831 | D56: 14.88 | E56: 56.360326 | F56: 1.8635
A57: 904 | B57: 33238 | C57: 375916 | D57: 13.95 | E57: 57.530704 | F57: 1.9439
... A198: 261 | B198: 46112 | C198: 710896 | D198: 3.75 | E198: 140.82497 | F198: 1.3484667

Sheet reconstruct_levels_ch
A1: date | B1: level CHCPI | C1: diff CPI SA | D1: level reconstructed | G1: level CHGDP | H1: DIFF gdp sa | I1: LEVEL RECONST
A2: 29281
A3: 29373
A4: 29465
A5: 29556
A6: 29646
A7: 29738
A8: 29830
A9: 29921
A10: 30011
A11: 30103
A12: 30195
A13: 30286
... A17: 30651
A18: 30742 | B18: =Haver!O28 -> 16.84
A19: 30834 | B19: =Haver!O29 -> 16.95 | C19: =Haver!P29 -> 0.0067228861 | D19: =B18*(1+C19) -> 16.953213
A20: 30926 | B20: =Haver!O30 -> 16.98 | C20: =Haver!P30 -> 0.0060729788 | D20: =D19*(1+C20) -> 17.05617
A21: 31017 | B21: =Haver!O31 -> 17.136667 | C21: =Haver!P31 -> 0.0090100711 | D21: =D20*(1+C21) -> 17.209847
A22: 31107 | B22: =Haver!O32 -> 17.91 | C22: =Haver!P32 -> 0.040991062 | D22: =D21*(1+C22) -> 17.915297
A23: 31199 | B23: =Haver!O33 -> 18.53 | C23: =Haver!P33 -> 0.034841861 | D23: =D22*(1+C23) -> 18.539499
A24: 31291 | B24: =Haver!O34 -> 18.876667 | C24: =Haver!P34 -> 0.022633036 | D24: =D23*(1+C24) -> 18.959105
A25: 31382 | B25: =Haver!O35 -> 19.063333 | C25: =Haver!P35 -> 0.0095166401 | D25: =D24*(1+C25) -> 19.139532
A26: 31472 | B26: =Haver!O36 -> 19.356667 | C26: =Haver!P36 -> 0.012038091 | D26: =D25*(1+C26) -> 19.369935
A27: 31564 | B27: =Haver!O37 -> 19.406667 | C27: =Haver!P37 -> 0.0027180194 | D27: =D26*(1+C27) -> 19.422583
A28: 31656 | B28: =Haver!O38 -> 19.66 | C28: =Haver!P38 -> 0.016208381 | D28: =D27*(1+C28) -> 19.737391
A29: 31747 | B29: =Haver!O39 -> 20.15 | C29: =Haver!P39 -> 0.024416901 | D29: =D28*(1+C29) -> 20.219317
A30: 31837 | B30: =Haver!O40 -> 20.446667 | C30: =Haver!P40 -> 0.012528852 | D30: =D29*(1+C30) -> 20.472642
A31: 31929 | B31: =Haver!O41 -> 20.876667 | C31: =Haver!P41 -> 0.021052688 | D31: =D30*(1+C31) -> 20.903646
... A49: 33573 | B49: =Haver!O59 -> 32.283333 | C49: =Haver!P59 -> 0.011817548 | D49: =D48*(1+C49) -> 32.338296
A50: 33664 | B50: =Haver!O60 -> 32.483333 | C50: =Haver!P60 -> 0.009765438 | D50: =D49*(1+C50) -> 32.654094 | G50: =Haver!E60 -> 2111.33 | I50: 2111.33
A51: 33756 | B51: =Haver!O61 -> 33.126667 | C51: =Haver!P61 -> 0.015189491 | D51: =D50*(1+C51) -> 33.150093 | H51: =Haver!F61 -> 0.04755739 | I51: =G50*(1+H51) -> 2211.7393
A52: 33848 | B52: =Haver!O62 -> 33.843333 | C52: =Haver!P62 -> 0.022675969 | D52: =D51*(1+C52) -> 33.901803 | H52: =Haver!F62 -> 0.036748155 | I52: =I51*(1+H52) -> 2293.0167
A53: 33939 | B53: =Haver!O63 -> 34.97 | C53: =Haver!P63 -> 0.033419174 | D53: =D52*(1+C53) -> 35.034773 | H53: =Haver!F63 -> 0.026937562 | I53: =I52*(1+H53) -> 2354.785
A54: 34029 | B54: =Haver!O64 -> 36.07 | C54: =Haver!P64 -> 0.034834188 | D54: =D53*(1+C54) -> 36.255181 | H54: =Haver!F64 -> 0.032272537 | I54: =I53*(1+H54) -> 2430.7798
A55: 34121 | B55: =Haver!O65 -> 37.786667 | C55: =Haver!P65 -> 0.043207519 | D55: =D54*(1+C55) -> 37.821678 | H55: =Haver!F65 -> 0.033564173 | I55: =I54*(1+H55) -> 2512.367
A56: 34213 | B56: =Haver!O66 -> 39.27 | C56: =Haver!P66 -> 0.040087394 | D56: =D55*(1+C56) -> 39.33785 | H56: =Haver!F66 -> 0.032376747 | I56: =I55*(1+H56) -> 2593.7092
A57: 34304 | B57: =Haver!O67 -> 40.976667 | C57: =Haver!P67 -> 0.043648965 | D57: =D56*(1+C57) -> 41.054907 | H57: =Haver!F67 -> 0.036458774 | I57: =I56*(1+H57) -> 2688.2727
A58: 34394 | B58: =Haver!O68 -> 44.02 | C58: =Haver!P68 -> 0.077386224 | D58: =D57*(1+C58) -> 44.231991 | H58: =Haver!F68 -> 0.029728603 | I58: =I57*(1+H58) -> 2768.1913
A59: 34486 | B59: =Haver!O69 -> 46.126667 | C59: =Haver!P69 -> 0.043952116 | D59: =D58*(1+C59) -> 46.17608 | H59: =Haver!F69 -> 0.03106403 | I59: =I58*(1+H59) -> 2854.1825
A60: 34578 | B60: =Haver!O70 -> 49.33 | C60: =Haver!P70 -> 0.069887828 | D60: =D59*(1+C60) -> 49.403226 | H60: =Haver!F70 -> 0.029805743 | I60: =I59*(1+H60) -> 2939.2535
...
